Workbook
Name AI_BIOMASS_STRATUM: AI_BIOMASS_STRATUM!$A$1:$I$55459
Name AI_BIOMASS_TOTAL: AI_BIOMASS_TOTAL!$A$1:$H$473

Sheet Readme
A2: Biomass is in metric tons
A3: Plots should focus on ESR groups, aggregated by ESR guild
A4: for questions please contact Ivonne.Ortiz@noaa.gov

Sheet AI_BIOMASS_TOTAL
A1: SURVEY | B1: YEAR | C1: SPECIES_CODE | D1: NAME | E1: TOTAL_BIOMASS | F1: BIOMASS_VAR | G1: MIN_BIOMASS | H1: MAX_BIOMASS | I1: ESR_GROUP | J1: ESR_GUILD
A2: AI | B2: 1991 | C2: 471 | D2: Alaska skate | E2: 1624.2 | F2: 661581.15 | G2: 0 | H2: 3548 | I2: AK Skate | J2: Apex predator
A3: AI | B3: 1994 | C3: 471 | D3: Alaska skate | E3: 7133.2 | F3: 2053659.4 | G3: 4181 | H3: 10085 | I3: AK Skate | J3: Apex predator
A4: AI | B4: 1997 | C4: 471 | D4: Alaska skate | E4: 7862.2 | F4: 1715258.8 | G4: 5188 | H4: 10537 | I4: AK Skate | J4: Apex predator
A5: AI | B5: 2000 | C5: 471 | D5: Alaska skate | E5: 9801.1 | F5: 2091081.3 | G5: 6802 | H5: 12800 | I5: AK Skate | J5: Apex predator
A6: AI | B6: 2002 | C6: 471 | D6: Alaska skate | E6: 10738.6 | F6: 4437563.4 | G6: 6481 | H6: 14996 | I6: AK Skate | J6: Apex predator
A7: AI | B7: 2004 | C7: 471 | D7: Alaska skate | E7: 12922.5 | F7: 8081618 | G7: 6950 | H7: 18895 | I7: AK Skate | J7: Apex predator
A8: AI | B8: 2006 | C8: 471 | D8: Alaska skate | E8: 13502.2 | F8: 6551158.1 | G8: 7925 | H8: 19079 | I8: AK Skate | J8: Apex predator
A9: AI | B9: 2010 | C9: 471 | D9: Alaska skate | E9: 3681.2 | F9: 564016.7 | G9: 2148 | H9: 5215 | I9: AK Skate | J9: Apex predator
A10: AI | B10: 2012 | C10: 471 | D10: Alaska skate | E10: 1503.1 | F10: 212348.5 | G10: 318 | H10: 2688 | I10: AK Skate | J10: Apex predator
A11: AI | B11: 2014 | C11: 471 | D11: Alaska skate | E11: 3514.9 | F11: 1941306.3 | G11: 0 | H11: 7097 | I11: AK Skate | J11: Apex predator
A12: AI | B12: 2016 | C12: 471 | D12: Alaska skate | E12: 1807.7 | F12: 679361.58 | G12: 0 | H12: 5354 | I12: AK Skate | J12: Apex predator
A13: AI | B13: 2018 | C13: 471 | D13: Alaska skate | E13: 2720.4 | F13: 309144.82 | G13: 951 | H13: 4490 | I13: AK Skate | J13: Apex predator
... A393: AI | B393: 2024 | C393: 21740 | D393: walleye pollock | E393: 196439.9 | F393: 4.8093819e+09 | G393: 36519 | H393: 356360 | I393: Walleye Pollock | J393: Pelagic forager

Sheet AI_BIOMASS_STRATUM
A1: SURVEY | B1: YEAR | C1: STRATUM | D1: SPECIES_CODE | E1: NAME | F1: STRATUM_BIOMASS | G1: BIOMASS_VAR | H1: MIN_BIOMASS | I1: MAX_BIOMASS | J1: Subregion | K1: ESR_GROUP | L1: ESR_GUILD
A2: AI | B2: 2024 | C2: 412 | D2: 471 | E2: AK Skate | F2: 7.7 | G2: 59.572501 | H2: 0 | I2: 24.5 | J2: =VLOOKUP(C2,STRATA_MASTER!$B$2:$C$53,2,FALSE) -> CentralALU | K2: AK Skate | L2: Apex predator
A3: AI | B3: 2024 | C3: 413 | D3: 471 | E3: AK Skate | F3: 0 | G3: 0 | H3: 0 | I3: 0 | J3: =VLOOKUP(C3,STRATA_MASTER!$B$2:$C$53,2,FALSE) -> CentralALU | K3: AK Skate | L3: Apex predator
A4: AI | B4: 2024 | C4: 211 | D4: 471 | E4: AK Skate | F4: 322.5 | G4: 62109.192 | H4: 0 | I4: 932.3 | J4: =VLOOKUP(C4,STRATA_MASTER!$B$2:$C$53,2,FALSE) -> WestALU | K4: AK Skate | L4: Apex predator
A5: AI | B5: 2024 | C5: 212 | D5: 471 | E5: AK Skate | F5: 11.1 | G5: 123.7801 | H5: 0 | I5: 33.8 | J5: =VLOOKUP(C5,STRATA_MASTER!$B$2:$C$53,2,FALSE) -> WestALU | K5: AK Skate | L5: Apex predator
A6: AI | B6: 2024 | C6: 213 | D6: 471 | E6: AK Skate | F6: 0 | G6: 0 | H6: 0 | I6: 0 | J6: =VLOOKUP(C6,STRATA_MASTER!$B$2:$C$53,2,FALSE) -> WestALU | K6: AK Skate | L6: Apex predator
A7: AI | B7: 2024 | C7: 214 | D7: 471 | E7: AK Skate | F7: 0 | G7: 0 | H7: 0 | I7: 0 | J7: =VLOOKUP(C7,STRATA_MASTER!$B$2:$C$53,2,FALSE) -> WestALU | K7: AK Skate | L7: Apex predator
A8: AI | B8: 2024 | C8: 221 | D8: 471 | E8: AK Skate | F8: 165.1 | G8: 10924.377 | H8: 0 | I8: 433.8 | J8: =VLOOKUP(C8,STRATA_MASTER!$B$2:$C$53,2,FALSE) -> WestALU | K8: AK Skate | L8: Apex predator
A9: AI | B9: 2024 | C9: 222 | D9: 471 | E9: AK Skate | F9: 0.7 | G9: 0.51197621 | H9: 0 | I9: 2.3 | J9: =VLOOKUP(C9,STRATA_MASTER!$B$2:$C$53,2,FALSE) -> WestALU | K9: AK Skate | L9: Apex predator
A10: AI | B10: 2024 | C10: 223 | D10: 471 | E10: AK Skate | F10: 63.3 | G10: 4004.3046 | H10: 0 | I10: 218.1 | J10: =VLOOKUP(C10,STRATA_MASTER!$B$2:$C$53,2,FALSE) -> WestALU | K10: AK Skate | L10: Apex predator
A11: AI | B11: 2024 | C11: 224 | D11: 471 | E11: AK Skate | F11: 0 | G11: 0 | H11: 0 | I11: 0 | J11: =VLOOKUP(C11,STRATA_MASTER!$B$2:$C$53,2,FALSE) -> WestALU | K11: AK Skate | L11: Apex predator
A12: AI | B12: 2024 | C12: 311 | D12: 471 | E12: AK Skate | F12: 112.1 | G12: 12571.329 | H12: 0 | I12: 468.9 | J12: =VLOOKUP(C12,STRATA_MASTER!$B$2:$C$53,2,FALSE) -> CentralALU | K12: AK Skate | L12: Apex predator
A13: AI | B13: 2024 | C13: 312 | D13: 471 | E13: AK Skate | F13: 0 | G13: 0 | H13: 0 | I13: 0 | J13: =VLOOKUP(C13,STRATA_MASTER!$B$2:$C$53,2,FALSE) -> CentralALU | K13: AK Skate | L13: Apex predator
... A588: AI | B588: 1991 | C588: 224 | D588: 471 | E588: AK Skate | F588: 0 | G588: 0 | H588: 0 | I588: 0 | J588: =VLOOKUP(C588,STRATA_MASTER!$B$2:$C$53,2,FALSE) -> WestALU | K588: AK Skate | L588: Apex predator
A589: AI | B589: 1991 | C589: 221 | D589: 471 | E589: AK Skate | F589: 0 | J589: =VLOOKUP(C589,STRATA_MASTER!$B$2:$C$53,2,FALSE) -> WestALU | K589: AK Skate | L589: Apex predator
A590: AI | B590: 1991 | C590: 222 | D590: 471 | E590: AK Skate | F590: 0 | G590: 0 | H590: 0 | I590: 0 | J590: =VLOOKUP(C590,STRATA_MASTER!$B$2:$C$53,2,FALSE) -> WestALU | K590: AK Skate | L590: Apex predator
A591: AI | B591: 1991 | C591: 211 | D591: 471 | E591: AK Skate | F591: 0 | G591: 0 | H591: 0 | I591: 0 | J591: =VLOOKUP(C591,STRATA_MASTER!$B$2:$C$53,2,FALSE) -> WestALU | K591: AK Skate | L591: Apex predator
A592: AI | B592: 1991 | C592: 212 | D592: 471 | E592: AK Skate | F592: 0 | G592: 0 | H592: 0 | I592: 0 | J592: =VLOOKUP(C592,STRATA_MASTER!$B$2:$C$53,2,FALSE) -> WestALU | K592: AK Skate | L592: Apex predator
A593: AI | B593: 1991 | C593: 213 | D593: 471 | E593: AK Skate | F593: 0 | G593: 0 | H593: 0 | I593: 0 | J593: =VLOOKUP(C593,STRATA_MASTER!$B$2:$C$53,2,FALSE) -> WestALU | K593: AK Skate | L593: Apex predator
A594: AI | B594: 1991 | C594: 214 | D594: 471 | E594: AK Skate | F594: 0 | G594: 0 | H594: 0 | I594: 0 | J594: =VLOOKUP(C594,STRATA_MASTER!$B$2:$C$53,2,FALSE) -> WestALU | K594: AK Skate | L594: Apex predator
A595: AI | B595: 1991 | C595: 312 | D595: 471 | E595: AK Skate | F595: 136 | G595: 7802.3389 | H595: 0 | I595: 325.4 | J595: =VLOOKUP(C595,STRATA_MASTER!$B$2:$C$53,2,FALSE) -> CentralALU | K595: AK Skate | L595: Apex predator
A596: AI | B596: 1991 | C596: 421 | D596: 471 | E596: AK Skate | F596: 115.9 | G596: 13423.321 | H596: 0 | I596: 1588 | J596: =VLOOKUP(C596,STRATA_MASTER!$B$2:$C$53,2,FALSE) -> CentralALU | K596: AK Skate | L596: Apex predator
A597: AI | B597: 1991 | C597: 622 | D597: 471 | E597: AK Skate | F597: 16.6 | G597: 274.17702 | H597: 0 | I597: 51.8 | J597: =VLOOKUP(C597,STRATA_MASTER!$B$2:$C$53,2,FALSE) -> EastALU | K597: AK Skate | L597: Apex predator
A598: AI | B598: 1991 | C598: 313 | D598: 471 | E598: AK Skate | F598: 53.8 | G598: 2892.1442 | H598: 0 | I598: 181 | J598: =VLOOKUP(C598,STRATA_MASTER!$B$2:$C$53,2,FALSE) -> CentralALU | K598: AK Skate | L598: Apex predator
A599: AI | B599: 1991 | C599: 623 | D599: 471 | E599: AK Skate | F599: 0 | G599: 0 | H599: 0 | I599: 0 | J599: =VLOOKUP(C599,STRATA_MASTER!$B$2:$C$53,2,FALSE) -> EastALU | K599: AK Skate | L599: Apex predator
A600: AI | B600: 1991 | C600: 314 | D600: 471 | E600: AK Skate | F600: 0 | G600: 0 | H600: 0 | I600: 0 | J600: =VLOOKUP(C600,STRATA_MASTER!$B$2:$C$53,2,FALSE) -> CentralALU | K600: AK Skate | L600: Apex predator
A601: AI | B601: 1991 | C601: 422 | D601: 471 | E601: AK Skate | F601: 0 | G601: 0 | H601: 0 | I601: 0 | J601: =VLOOKUP(C601,STRATA_MASTER!$B$2:$C$53,2,FALSE) -> CentralALU | K601: AK Skate | L601: Apex predator
... A606: AI | B606: 1991 | C606: 712 | D606: 471 | E606: AK Skate | F606: 0 | G606: 0 | H606: 0 | I606: 0 | J606: =VLOOKUP(C606,STRATA_MASTER!$B$2:$C$53,2,FALSE) -> Aleutian Arm | K606: AK Skate | L606: Apex predator
A607: AI | B607: 1991 | C607: 424 | D607: 471 | E607: AK Skate | F607: 0 | J607: =VLOOKUP(C607,STRATA_MASTER!$B$2:$C$53,2,FALSE) -> CentralALU | K607: AK Skate | L607: Apex predator
A608: AI | B608: 1991 | C608: 721 | D608: 471 | E608: AK Skate | F608: 0 | G608: 0 | H608: 0 | I608: 0 | J608: =VLOOKUP(C608,STRATA_MASTER!$B$2:$C$53,2,FALSE) -> Aleutian Arm | K608: AK Skate | L608: Apex predator
A609: AI | B609: 1991 | C609: 511 | D609: 471 | E609: AK Skate | F609: 102.3 | G609: 4657.244 | H609: 0 | I609: 277.8 | J609: =VLOOKUP(C609,STRATA_MASTER!$B$2:$C$53,2,FALSE) -> EastALU | K609: AK Skate | L609: Apex predator
A610: AI | B610: 1991 | C610: 722 | D610: 471 | E610: AK Skate | F610: 0 | G610: 0 | H610: 0 | I610: 0 | J610: =VLOOKUP(C610,STRATA_MASTER!$B$2:$C$53,2,FALSE) -> Aleutian Arm | K610: AK Skate | L610: Apex predator
A611: AI | B611: 1991 | C611: 322 | D611: 471 | E611: AK Skate | F611: 23.5 | G611: 554.41566 | H611: 0 | I611: 77.8 | J611: =VLOOKUP(C611,STRATA_MASTER!$B$2:$C$53,2,FALSE) -> CentralALU | K611: AK Skate | L611: Apex predator
A612: AI | B612: 1991 | C612: 512 | D612: 471 | E612: AK Skate | F612: 42.3 | G612: 361.01208 | H612: 1.9 | I612: 82.8 | J612: =VLOOKUP(C612,STRATA_MASTER!$B$2:$C$53,2,FALSE) -> EastALU | K612: AK Skate | L612: Apex predator
A613: AI | B613: 1991 | C613: 513 | D613: 471 | E613: AK Skate | F613: 0 | J613: =VLOOKUP(C613,STRATA_MASTER!$B$2:$C$53,2,FALSE) -> EastALU | K613: AK Skate | L613: Apex predator
A614: AI | B614: 1991 | C614: 793 | D614: 471 | E614: AK Skate | F614: 0 | G614: 0 | H614: 0 | I614: 0 | J614: =VLOOKUP(C614,STRATA_MASTER!$B$2:$C$53,2,FALSE) -> Aleutian Arm | K614: AK Skate | L614: Apex predator
A615: AI | B615: 1991 | C615: 794 | D615: 471 | E615: AK Skate | F615: 0 | G615: 0 | H615: 0 | I615: 0 | J615: =VLOOKUP(C615,STRATA_MASTER!$B$2:$C$53,2,FALSE) -> Aleutian Arm | K615: AK Skate | L615: Apex predator
A616: AI | B616: 1991 | C616: 521 | D616: 471 | E616: AK Skate | F616: 25.1 | G616: 628.95245 | H616: 0 | I616: 104.9 | J616: =VLOOKUP(C616,STRATA_MASTER!$B$2:$C$53,2,FALSE) -> EastALU | K616: AK Skate | L616: Apex predator
A617: AI | B617: 1991 | C617: 522 | D617: 471 | E617: AK Skate | F617: 15.7 | G617: 245.49587 | H617: 0 | I617: 48.6 | J617: =VLOOKUP(C617,STRATA_MASTER!$B$2:$C$53,2,FALSE) -> EastALU | K617: AK Skate | L617: Apex predator
A618: AI | B618: 1991 | C618: 323 | D618: 471 | E618: AK Skate | F618: 0 | G618: 0 | H618: 0 | I618: 0 | J618: =VLOOKUP(C618,STRATA_MASTER!$B$2:$C$53,2,FALSE) -> CentralALU | K618: AK Skate | L618: Apex predator
...

Sheet guilds
A1: Code | B1: Taxa | C1: Group | D1: Guild
A2: 400 | B2: Rajidae | C2: Other skates | D2: Apex predator
A3: 405 | B3: Bathyraja sp. | C3: Other skates | D3: Apex predator
A4: 420 | B4: Raja binoculata | C4: Other skates | D4: Apex predator
A5: 435 | B5: Bathyraja interrupta | C5: Other skates | D5: Apex predator
A6: 440 | B6: Raja rhina | C6: Other skates | D6: Apex predator
A7: 455 | B7: Bathyraja taranetzi | C7: Other skates | D7: Apex predator
A8: 460 | B8: Bathyraja trachura | C8: Other skates | D8: Apex predator
A9: 471 | B9: Bathyraja parmifera | C9: AK Skate | D9: Apex predator
A10: 472 | B10: Bathyraja aleutica | C10: Other skates | D10: Apex predator
A11: 480 | B11: Bathyraja maculata | C11: Other skates | D11: Apex predator
A12: 485 | B12: Bathyraja minispinosa | C12: Other skates | D12: Apex predator
A13: 10110 | B13: Atheresthes stomias | C13: Arrowtooth flounder | D13: Apex predator
... A24: 21921 | B24: Pleurogrammus monopterygius | C24: Atka mackerel | D24: Pelagic forager
A25: 30050 | B25: 0 | C25: Rougheye/ Blackspotted Rockfish | D25: Apex predator
A26: 30051 | B26: Sebastes aleutianus | C26: Rougheye/ Blackspotted Rockfish | D26: Apex predator
A27: 30052 | B27: Sebastes melanostictus | C27: Rougheye/ Blackspotted Rockfish | D27: Apex predator
A28: 30060 | B28: Sebastes alutus | C28: Pacific ocean perch | D28: Pelagic forager
A29: 30420 | B29: Sebastes polyspinis | C29: Northern Rockfish | D29: Pelagic forager

Sheet STRATA_MASTER
A1: Ecoystem | B1: strata | C1: LocalandPLPool | D1: PPDietWeightPool | E1: Area | F1: min depth | G1: max depth | H1: Description
A2: ALU | B2: 0 | C2: NA | D2: NA | E2: 1 | F2: 0 | G2: 0 | H2: NA
A3: ALU | B3: 7 | C3: NA | D3: NA | E3: 1 | F3: 0 | G3: 0 | H3: NA
A4: ALU | B4: 211 | C4: WestALU | D4: WestALUShallow | E4: 3696.321 | F4: 0 | G4: 100 | H4: Stalemate bank & Attu I
A5: ALU | B5: 212 | C5: WestALU | D5: WestALUMiddle | E5: 4065.172 | F5: 100 | G5: 200 | H5: Stalemate bank & Attu I
A6: ALU | B6: 213 | C6: WestALU | D6: WestALUDeep | E6: 940.226 | F6: 200 | G6: 300 | H6: Stalemate bank & Attu I
A7: ALU | B7: 214 | C7: WestALU | D7: WestALUDeep | E7: 1711.084 | F7: 300 | G7: 500 | H7: Stalemate bank & Attu I
A8: ALU | B8: 221 | C8: WestALU | D8: WestALUShallow | E8: 1183.328 | F8: 0 | G8: 100 | H8: Buldir I.
A9: ALU | B9: 222 | C9: WestALU | D9: WestALUMiddle | E9: 1252.459 | F9: 100 | G9: 200 | H9: Buldir I.
A10: ALU | B10: 223 | C10: WestALU | D10: WestALUDeep | E10: 783.403 | F10: 200 | G10: 300 | H10: Buldir I.
A11: ALU | B11: 224 | C11: WestALU | D11: WestALUDeep | E11: 1561.386 | F11: 300 | G11: 500 | H11: Buldir I.
A12: ALU | B12: 311 | C12: CentralALU | D12: CentALUShallow | E12: 960.023 | F12: 0 | G12: 100 | H12: Petrel Bank
A13: ALU | B13: 312 | C13: CentralALU | D13: CentALUMiddle | E13: 1735.544 | F13: 100 | G13: 200 | H13: Petrel Bank
... A53: EBS | B53: 794 | C53: Aleutian Arm | D53: ALU 700 Deep | E53: 1043.168 | F53: 301 | G53: 500 | H53: North portion of both Umnak I. & Unalaska I.
